<?xml version="1.0" encoding="UTF-8"?><magicdraw><comment classType="Comment" humanType="Comment" icon="index_files/icon_comment_2051026490.jpg" id="_10_5_622020d_1132928310172_126267_6560"><annotatedElement humanName="Annotated Element" mode="s,e"><class classType="Class" humanType="Class" icon="index_files/icon_class_1555793073.jpg" name="ExecutionException" refid="_10_5_622020d_1132928310172_229661_6558"/></annotatedElement><body humanName="Body" mode="s,e">Exception thrown when attempting to retrieve the result of a task
that aborted by throwing an exception. This exception can be
inspected using the {@link #getCause()} method.

@see Future
@since 1.5
@author Doug Lea
</body><documentation humanName="Documentation"/><owner classType="Class" humanName="Owner" humanType="Class" icon="index_files/icon_class_1555793073.jpg" mode="s,e" name="ExecutionException" refid="_10_5_622020d_1132928310172_229661_6558"/><owningElement classType="Class" humanName="Owning Element" humanType="Class" icon="index_files/icon_class_1555793073.jpg" name="ExecutionException" refid="_10_5_622020d_1132928310172_229661_6558"/><TO_DO humanName="To Do" mode="s,e"/></comment></magicdraw>